[32m2025-06-05 16:16:01 +0700[0m - dagster - [34mDEBUG[0m - adhoc_job - c3bc7fbc-04d0-4b11-b656-e85a4cfe8926 - 913156 - LOGS_CAPTURED - Started capturing logs in process (pid: 913156).
[32m2025-06-05 16:16:01 +0700[0m - dagster - [34mDEBUG[0m - adhoc_job - c3bc7fbc-04d0-4b11-b656-e85a4cfe8926 - 913156 - adhoc_daily_transaction_forecast - STEP_START - Started execution of step "adhoc_daily_transaction_forecast".
/home/tunguyenn99/project/dagster-dlt-mdb-snf/dagster-mdb-analytics/dagster_mdb_analytics/assets/adhoc.py:31: UserWarning: pandas only supports SQLAlchemy connectable (engine/connection) or database string URI or sqlite3 DBAPI2 connection. Other DBAPI2 objects are not tested. Please consider using SQLAlchemy.
  df = pd.read_sql(query, conn)
[32m2025-06-05 16:17:04 +0700[0m - dagster - [34mERROR[0m - [31madhoc_job - c3bc7fbc-04d0-4b11-b656-e85a4cfe8926 - 913156 - adhoc_daily_transaction_forecast - STEP_FAILURE - Execution of step "adhoc_daily_transaction_forecast" failed.

dagster._core.errors.DagsterExecutionStepExecutionError: Error occurred while executing op "adhoc_daily_transaction_forecast"::

ValueError: Dataframe must have columns "ds" and "y" with the dates and values respectively.

Stack Trace:
  File "/home/tunguyenn99/project/dagster-dlt-mdb-snf/venv/lib/python3.8/site-packages/dagster/_core/execution/plan/utils.py", line 54, in op_execution_error_boundary
    yield
  File "/home/tunguyenn99/project/dagster-dlt-mdb-snf/venv/lib/python3.8/site-packages/dagster/_utils/__init__.py", line 482, in iterate_with_context
    next_output = next(iterator)
  File "/home/tunguyenn99/project/dagster-dlt-mdb-snf/venv/lib/python3.8/site-packages/dagster/_core/execution/plan/compute_generator.py", line 140, in _coerce_op_compute_fn_to_iterator
    result = invoke_compute_fn(
  File "/home/tunguyenn99/project/dagster-dlt-mdb-snf/venv/lib/python3.8/site-packages/dagster/_core/execution/plan/compute_generator.py", line 128, in invoke_compute_fn
    return fn(context, **args_to_pass) if context_arg_provided else fn(**args_to_pass)
  File "/home/tunguyenn99/project/dagster-dlt-mdb-snf/dagster-mdb-analytics/dagster_mdb_analytics/assets/adhoc.py", line 35, in adhoc_daily_transaction_forecast
    model.fit(df)
  File "/home/tunguyenn99/project/dagster-dlt-mdb-snf/venv/lib/python3.8/site-packages/prophet/forecaster.py", line 1220, in fit
    model_inputs = self.preprocess(df, **kwargs)
  File "/home/tunguyenn99/project/dagster-dlt-mdb-snf/venv/lib/python3.8/site-packages/prophet/forecaster.py", line 1129, in preprocess
    raise ValueError(
[0m
