[32m2025-06-05 12:39:31 +0700[0m - dagster - [34mDEBUG[0m - __ASSET_JOB - 71831ea5-8b44-4bfd-a66d-e2c3ecd1af57 - 375019 - LOGS_CAPTURED - Started capturing logs in process (pid: 375019).
[32m2025-06-05 12:39:31 +0700[0m - dagster - [34mDEBUG[0m - __ASSET_JOB - 71831ea5-8b44-4bfd-a66d-e2c3ecd1af57 - 375019 - top_stocks_by_transaction_volume - STEP_START - Started execution of step "top_stocks_by_transaction_volume".
[32m2025-06-05 12:39:32 +0700[0m - dagster - [34mERROR[0m - [31m__ASSET_JOB - 71831ea5-8b44-4bfd-a66d-e2c3ecd1af57 - 375019 - top_stocks_by_transaction_volume - STEP_FAILURE - Execution of step "top_stocks_by_transaction_volume" failed.

dagster._core.errors.DagsterExecutionStepExecutionError: Error occurred while executing op "top_stocks_by_transaction_volume"::

ValueError: Could not interpret value `stock` for `y`. An entry with this name does not appear in `data`.

Stack Trace:
  File "/home/tunguyenn99/project/dagster-dlt-mdb-snf/venv/lib/python3.8/site-packages/dagster/_core/execution/plan/utils.py", line 54, in op_execution_error_boundary
    yield
  File "/home/tunguyenn99/project/dagster-dlt-mdb-snf/venv/lib/python3.8/site-packages/dagster/_utils/__init__.py", line 482, in iterate_with_context
    next_output = next(iterator)
  File "/home/tunguyenn99/project/dagster-dlt-mdb-snf/venv/lib/python3.8/site-packages/dagster/_core/execution/plan/compute_generator.py", line 140, in _coerce_op_compute_fn_to_iterator
    result = invoke_compute_fn(
  File "/home/tunguyenn99/project/dagster-dlt-mdb-snf/venv/lib/python3.8/site-packages/dagster/_core/execution/plan/compute_generator.py", line 128, in invoke_compute_fn
    return fn(context, **args_to_pass) if context_arg_provided else fn(**args_to_pass)
  File "/home/tunguyenn99/project/dagster-dlt-mdb-snf/dagster-mdb-analytics/dagster_mdb_analytics/assets/transactions.py", line 66, in top_stocks_by_transaction_volume
    ax = sns.barplot(
  File "/home/tunguyenn99/project/dagster-dlt-mdb-snf/venv/lib/python3.8/site-packages/seaborn/categorical.py", line 2341, in barplot
    p = _CategoricalAggPlotter(
  File "/home/tunguyenn99/project/dagster-dlt-mdb-snf/venv/lib/python3.8/site-packages/seaborn/categorical.py", line 67, in __init__
    super().__init__(data=data, variables=variables)
  File "/home/tunguyenn99/project/dagster-dlt-mdb-snf/venv/lib/python3.8/site-packages/seaborn/_base.py", line 634, in __init__
    self.assign_variables(data, variables)
  File "/home/tunguyenn99/project/dagster-dlt-mdb-snf/venv/lib/python3.8/site-packages/seaborn/_base.py", line 679, in assign_variables
    plot_data = PlotData(data, variables)
  File "/home/tunguyenn99/project/dagster-dlt-mdb-snf/venv/lib/python3.8/site-packages/seaborn/_core/data.py", line 58, in __init__
    frame, names, ids = self._assign_variables(data, variables)
  File "/home/tunguyenn99/project/dagster-dlt-mdb-snf/venv/lib/python3.8/site-packages/seaborn/_core/data.py", line 232, in _assign_variables
    raise ValueError(err)
[0m
