[32m2025-06-05 12:35:40 +0700[0m - dagster - [34mDEBUG[0m - __ASSET_JOB - 34bfdfd3-decb-467e-bb90-5cac71fa5a95 - 363548 - LOGS_CAPTURED - Started capturing logs in process (pid: 363548).
[32m2025-06-05 12:35:40 +0700[0m - dagster - [34mDEBUG[0m - __ASSET_JOB - 34bfdfd3-decb-467e-bb90-5cac71fa5a95 - 363548 - cleaned_transactions - STEP_START - Started execution of step "cleaned_transactions".
[32m2025-06-05 12:35:47 +0700[0m - dagster - [34mERROR[0m - [31m__ASSET_JOB - 34bfdfd3-decb-467e-bb90-5cac71fa5a95 - 363548 - cleaned_transactions - STEP_FAILURE - Execution of step "cleaned_transactions" failed.

dagster._core.errors.DagsterExecutionStepExecutionError: Error occurred while executing op "cleaned_transactions"::

KeyError: 'volume'

Stack Trace:
  File "/home/tunguyenn99/project/dagster-dlt-mdb-snf/venv/lib/python3.8/site-packages/dagster/_core/execution/plan/utils.py", line 54, in op_execution_error_boundary
    yield
  File "/home/tunguyenn99/project/dagster-dlt-mdb-snf/venv/lib/python3.8/site-packages/dagster/_utils/__init__.py", line 482, in iterate_with_context
    next_output = next(iterator)
  File "/home/tunguyenn99/project/dagster-dlt-mdb-snf/venv/lib/python3.8/site-packages/dagster/_core/execution/plan/compute_generator.py", line 140, in _coerce_op_compute_fn_to_iterator
    result = invoke_compute_fn(
  File "/home/tunguyenn99/project/dagster-dlt-mdb-snf/venv/lib/python3.8/site-packages/dagster/_core/execution/plan/compute_generator.py", line 128, in invoke_compute_fn
    return fn(context, **args_to_pass) if context_arg_provided else fn(**args_to_pass)
  File "/home/tunguyenn99/project/dagster-dlt-mdb-snf/dagster-mdb-analytics/dagster_mdb_analytics/assets/transactions.py", line 33, in cleaned_transactions
    df = df[df["volume"] > 0]  # l·ªçc giao d·ªãch l·ªói
  File "/home/tunguyenn99/project/dagster-dlt-mdb-snf/venv/lib/python3.8/site-packages/pandas/core/frame.py", line 3761, in __getitem__
    indexer = self.columns.get_loc(key)
  File "/home/tunguyenn99/project/dagster-dlt-mdb-snf/venv/lib/python3.8/site-packages/pandas/core/indexes/base.py", line 3655, in get_loc
    raise KeyError(key) from err

The above exception was caused by the following exception:
KeyError: 'volume'

Stack Trace:
  File "/home/tunguyenn99/project/dagster-dlt-mdb-snf/venv/lib/python3.8/site-packages/pandas/core/indexes/base.py", line 3653, in get_loc
    return self._engine.get_loc(casted_key)
  File "pandas/_libs/index.pyx", line 147, in pandas._libs.index.IndexEngine.get_loc
  File "pandas/_libs/index.pyx", line 176, in pandas._libs.index.IndexEngine.get_loc
  File "pandas/_libs/hashtable_class_helper.pxi", line 7080, in pandas._libs.hashtable.PyObjectHashTable.get_item
  File "pandas/_libs/hashtable_class_helper.pxi", line 7088, in pandas._libs.hashtable.PyObjectHashTable.get_item
[0m
