[32m2025-06-05 14:37:28 +0700[0m - dagster - [34mDEBUG[0m - __ASSET_JOB - 71c09bd1-7267-4af3-afbb-ba9754db21cf - 651436 - LOGS_CAPTURED - Started capturing logs in process (pid: 651436).
[32m2025-06-05 14:37:28 +0700[0m - dagster - [34mDEBUG[0m - __ASSET_JOB - 71c09bd1-7267-4af3-afbb-ba9754db21cf - 651436 - accounts_flattened_products - STEP_START - Started execution of step "accounts_flattened_products".
/home/tunguyenn99/project/dagster-dlt-mdb-snf/dagster-mdb-analytics/dagster_mdb_analytics/assets/transactions.py:147: UserWarning: pandas only supports SQLAlchemy connectable (engine/connection) or database string URI or sqlite3 DBAPI2 connection. Other DBAPI2 objects are not tested. Please consider using SQLAlchemy.
  df = pd.read_sql(query, conn)
[32m2025-06-05 14:37:34 +0700[0m - dagster - [34mERROR[0m - [31m__ASSET_JOB - 71c09bd1-7267-4af3-afbb-ba9754db21cf - 651436 - accounts_flattened_products - STEP_FAILURE - Execution of step "accounts_flattened_products" failed.

dagster._core.errors.DagsterExecutionStepExecutionError: Error occurred while executing op "accounts_flattened_products"::

KeyError: 'product'

Stack Trace:
  File "/home/tunguyenn99/project/dagster-dlt-mdb-snf/venv/lib/python3.8/site-packages/dagster/_core/execution/plan/utils.py", line 54, in op_execution_error_boundary
    yield
  File "/home/tunguyenn99/project/dagster-dlt-mdb-snf/venv/lib/python3.8/site-packages/dagster/_utils/__init__.py", line 482, in iterate_with_context
    next_output = next(iterator)
  File "/home/tunguyenn99/project/dagster-dlt-mdb-snf/venv/lib/python3.8/site-packages/dagster/_core/execution/plan/compute_generator.py", line 140, in _coerce_op_compute_fn_to_iterator
    result = invoke_compute_fn(
  File "/home/tunguyenn99/project/dagster-dlt-mdb-snf/venv/lib/python3.8/site-packages/dagster/_core/execution/plan/compute_generator.py", line 128, in invoke_compute_fn
    return fn(context, **args_to_pass) if context_arg_provided else fn(**args_to_pass)
  File "/home/tunguyenn99/project/dagster-dlt-mdb-snf/dagster-mdb-analytics/dagster_mdb_analytics/assets/transactions.py", line 149, in accounts_flattened_products
    df['product'] = df['product'].str.strip()
  File "/home/tunguyenn99/project/dagster-dlt-mdb-snf/venv/lib/python3.8/site-packages/pandas/core/frame.py", line 3761, in __getitem__
    indexer = self.columns.get_loc(key)
  File "/home/tunguyenn99/project/dagster-dlt-mdb-snf/venv/lib/python3.8/site-packages/pandas/core/indexes/base.py", line 3655, in get_loc
    raise KeyError(key) from err

The above exception was caused by the following exception:
KeyError: 'product'

Stack Trace:
  File "/home/tunguyenn99/project/dagster-dlt-mdb-snf/venv/lib/python3.8/site-packages/pandas/core/indexes/base.py", line 3653, in get_loc
    return self._engine.get_loc(casted_key)
  File "pandas/_libs/index.pyx", line 147, in pandas._libs.index.IndexEngine.get_loc
  File "pandas/_libs/index.pyx", line 176, in pandas._libs.index.IndexEngine.get_loc
  File "pandas/_libs/hashtable_class_helper.pxi", line 7080, in pandas._libs.hashtable.PyObjectHashTable.get_item
  File "pandas/_libs/hashtable_class_helper.pxi", line 7088, in pandas._libs.hashtable.PyObjectHashTable.get_item
[0m
